<?xml version="1.0" ?>
<robot name="starbot" xmlns:xacro="http://ros.org/wiki/xacro">
    
    <!--- new_gazebo_version should be false by default because pinocchio needs it!-->
    <xacro:arg name="robot_name" default="starbot"/> 
    <xacro:arg name="new_gazebo_version" default="false"/>	


    <xacro:include filename="$(find starbot_description)/gazebo/gazebo.urdf.xacro">
        <xacro:arg name="task_period" value="$(arg task_period)"/>
	<xacro:arg name="robot_name" value="$(arg robot_name)"/>
    </xacro:include>

    <xacro:include filename="$(find starbot_description)/urdfs/leg.xacro"/>

    <!-- BASE LINK -->
    <!-- floating type is supported in older versions of Gazebo. In new Gazebo if a link has no parent, it is supposed to be attached to a floating joint -->

    <xacro:unless value="$(arg new_gazebo_version)">  
        <!-- Floating-base Joint -->
        <link name="world"/>
        <joint name="floating_base_joint" type="floating" >
            <origin rpy="0 0 0" xyz="0 0 0"/>
            <parent link="world"/>
            <child link="base_link"/>
        </joint>
    </xacro:unless>

    <link name="base_link" />    
    <joint name="floating_base" type="fixed">
        <origin rpy="0 0 0" xyz="0 0 0"/>
        <parent link="base_link"/>
        <child link="trunk"/>
    </joint>



    
    <link name="trunk">
        <inertial>
        <origin xyz="0 0 0" rpy="0 0 0"/>
        <mass value="20.0"/>
        <inertia ixx="0.16574" ixy="0" ixz="0" iyy="0.16574" iyz="0" izz="0.24057"/>
      </inertial>
      <visual>
        <origin xyz="0 0 0" rpy="0 0 0"/>
        <geometry>
           <mesh filename="package://starbot_description/meshes/stl/octagon.stl"/>
        </geometry>
        <material name="body_color">
        	<color rgba="0.8 0.8 0.8 1.0"/>
        </material>
      </visual>
      <collision>
        <origin xyz="0 0 0" rpy="0 0 0"/>
        <geometry>
          <box size="0.27816 0.27816 0.2"/>
        </geometry>
      </collision>
    </link>

    
    <!-- LEFT FRONT LEG -->
     <xacro:leg
    	name="lf"
    	parent="base_link"
    	is_front="true"
    	is_right="false"
    	robot_name="$(arg robot_name)">
    	<origin xyz="0.14142 0.00035 2e-05" rpy="0 0 0"/>
    </xacro:leg>

    <!-- RIGHT FRONT LEG -->
    <xacro:leg
    	name="rf"
    	parent="base_link"
    	is_front="true"
    	is_right="true"
    	robot_name="$(arg robot_name)">
    	<origin xyz="-0.00035 0.14142 2e-05" rpy="0 0 0"/>
    </xacro:leg>

    <!-- LEFT HIND LEG -->
     <xacro:leg
    	name="lh"
    	parent="base_link"
    	is_front="false"
    	is_right="false"
    	robot_name="$(arg robot_name)">
    	<origin xyz="-0.00035 -0.14142 2e-05" rpy="0 0 0"/>
    </xacro:leg>

    <!-- RIGHT HIND LEG -->
    <xacro:leg
    	name="rh"
    	parent="base_link"
    	is_front="false"
    	is_right="true"
    	robot_name="$(arg robot_name)">
    	<origin xyz="-0.14142 0.00035 2e-05" rpy="0 0 0"/>
    </xacro:leg>


    
</robot>
